Workbook

Sheet Run distances
A1: Rise and Run Club
B2: Distance per lap (km): | D2: 0.3
E3: Week 2 | J3: Week 3 | O3: Week 4 | T3: Week 5 | Y3: Week 6 | AD3: Week 7 | AI3: Week 8 | AN3: Week 9 | AS3: Week 10 | AX3: Week 11
A4: Student Name | B4: Year | C4: House | D4: Care Group | E4: Tuesday | F4: Wednesday | G4: Thursday | H4: Friday | J4: Tuesday | K4: Wednesday | L4: Thursday | M4: Friday | O4: Tuesday | P4: Wednesday | Q4: Thursday | R4: Friday | T4: Tuesday | U4: Wednesday | V4: Thursday | W4: Friday | Y4: Tuesday | Z4: Wednesday | AA4: Thursday | AB4: Friday | AD4: Tuesday | AE4: Wednesday | AF4: Thursday | AG4: Friday | AI4: Tuesday | AJ4: Wednesday | AK4: Thursday | AL4: Friday | AN4: Tuesday | AO4: Wednesday | AP4: Thursday | AQ4: Friday | AS4: Tuesday | AT4: Wednesday | AU4: Thursday | AV4: Friday | AX4: Tuesday | AY4: Wednesday | AZ4: Thursday | BA4: Friday | BC4: Total Term Laps | BD4: Total Year Distance (km) | BE4: Total Term 1 Distance (km)
A5: HARPER J | B5: 1 | C5: SPENCER | D5: 1/2LC | E5: 0 | F5: 0 | G5: 0 | H5: 1 | L5: 1 | P5: 2 | BC5: =SUM(E5:BA5) -> 4 | BD5: =(SUM(BE5,'Run distances (Term 2)'!BI5,'Run distances (Term 3)'!BI5,'Run distances (Term 4)'!BI5)) -> 3.3 | BE5: =(SUM(E5:BB5)*$D$2) -> 1.2
A6: BEN W | B6: 1 | C6: SPENCER | D6: R/1ZG | BC6: =SUM(E6:BA6) -> 0 | BD6: =(SUM(BE6,'Run distances (Term 2)'!BI6,'Run distances (Term 3)'!BI6,'Run distances (Term 4)'!BI6)) -> 0.9 | BE6: =(SUM(E6:BB6)*$D$2) -> 0
A7: RYLEE M | B7: 1 | C7: SPENCER | D7: R/1ZG | BC7: =SUM(E7:BA7) -> 0 | BD7: =(SUM(BE7,'Run distances (Term 2)'!BI7,'Run distances (Term 3)'!BI7,'Run distances (Term 4)'!BI7)) -> 0.6 | BE7: =(SUM(E7:BB7)*$D$2) -> 0
A8: PEYTON V | B8: 1 | C8: SPENCER | D8: R/1ZG | BC8: =SUM(E8:BA8) -> 0 | BD8: =(SUM(BE8,'Run distances (Term 2)'!BI8,'Run distances (Term 3)'!BI8,'Run distances (Term 4)'!BI8)) -> 0.9 | BE8: =(SUM(E8:BB8)*$D$2) -> 0
A9: MAGGIE S | B9: 1 | C9: SPENCER | D9: R/1ZG | BC9: =SUM(E9:BA9) -> 0 | BD9: =(SUM(BE9,'Run distances (Term 2)'!BI9,'Run distances (Term 3)'!BI9,'Run distances (Term 4)'!BI9)) -> 12.3 | BE9: =(SUM(E9:BB9)*$D$2) -> 0
A10: ROSIE C | B10: 2 | C10: SPENCER | D10: 1/2LC | E10: 0 | F10: 0 | G10: 4 | H10: 2 | L10: 1 | Q10: 4 | T10: 1 | U10: 1 | Z10: 1 | AP10: 3 | AZ10: 4 | BC10: =SUM(E10:BA10) -> 21 | BD10: =(SUM(BE10,'Run distances (Term 2)'!BI10,'Run distances (Term 3)'!BI10,'Run distances (Term 4)'!BI10)) -> 10.2 | BE10: =(SUM(E10:BB10)*$D$2) -> 6.3
A11: ERIC D | B11: 2 | C11: SPENCER | D11: 1/2LC | E11: 1 | F11: 0 | G11: 2 | H11: 1 | P11: 3 | BC11: =SUM(E11:BA11) -> 7 | BD11: =(SUM(BE11,'Run distances (Term 2)'!BI11,'Run distances (Term 3)'!BI11,'Run distances (Term 4)'!BI11)) -> 2.4 | BE11: =(SUM(E11:BB11)*$D$2) -> 2.1
A12: HARRISON J | B12: 2 | C12: SPENCER | D12: 1/2LC | E12: 1 | F12: 0 | G12: 1 | H12: 4 | BC12: =SUM(E12:BA12) -> 6 | BD12: =(SUM(BE12,'Run distances (Term 2)'!BI12,'Run distances (Term 3)'!BI12,'Run distances (Term 4)'!BI12)) -> 6.9 | BE12: =(SUM(E12:BB12)*$D$2) -> 1.8
A13: LELAND J | B13: 2 | C13: SPENCER | D13: 1/2LC | E13: 0 | F13: 0 | G13: 2 | H13: 1 | BC13: =SUM(E13:BA13) -> 3 | BD13: =(SUM(BE13,'Run distances (Term 2)'!BI13,'Run distances (Term 3)'!BI13,'Run distances (Term 4)'!BI13)) -> 1.5 | BE13: =(SUM(E13:BB13)*$D$2) -> 0.9
A14: BILLY K | B14: 2 | C14: SPENCER | D14: 1/2LC | E14: 1 | F14: 0 | G14: 5 | H14: 0 | L14: 2 | BC14: =SUM(E14:BA14) -> 8 | BD14: =(SUM(BE14,'Run distances (Term 2)'!BI14,'Run distances (Term 3)'!BI14,'Run distances (Term 4)'!BI14)) -> 2.4 | BE14: =(SUM(E14:BB14)*$D$2) -> 2.4
A15: ALEX Y | B15: 2 | C15: SPENCER | D15: 1/2LC | BC15: =SUM(E15:BA15) -> 0 | BD15: =(SUM(BE15,'Run distances (Term 2)'!BI15,'Run distances (Term 3)'!BI15,'Run distances (Term 4)'!BI15)) -> 0 | BE15: =(SUM(E15:BB15)*$D$2) -> 0
A16: CONNOR C | B16: 10 | C16: SPENCER | D16: 10CF | M16: 1 | BC16: =SUM(E16:BA16) -> 1 | BD16: =(SUM(BE16,'Run distances (Term 2)'!BI16,'Run distances (Term 3)'!BI16,'Run distances (Term 4)'!BI16)) -> 3.3 | BE16: =(SUM(E16:BB16)*$D$2) -> 0.3
A17: HALEIGH S | B17: 10 | C17: SPENCER | D17: 10CF | Z17: 1 | AA17: 1 | BC17: =SUM(E17:BA17) -> 2 | BD17: =(SUM(BE17,'Run distances (Term 2)'!BI17,'Run distances (Term 3)'!BI17,'Run distances (Term 4)'!BI17)) -> 0.6 | BE17: =(SUM(E17:BB17)*$D$2) -> 0.6
A18: ANAIS G | B18: 10 | C18: SPENCER | D18: 10CF | J18: 0 | K18: 2 | L18: 3 | M18: 3 | Q18: 3 | R18: 1 | U18: 4 | W18: 1 | BC18: =SUM(E18:BA18) -> 17 | BD18: =(SUM(BE18,'Run distances (Term 2)'!BI18,'Run distances (Term 3)'!BI18,'Run distances (Term 4)'!BI18)) -> 7.2 | BE18: =(SUM(E18:BB18)*$D$2) -> 5.1
A19: AXYL W | B19: 11 | C19: SPENCER | D19: 11DF | E19: 0 | F19: 0 | G19: 2 | H19: 0 | M19: 2 | BC19: =SUM(E19:BA19) -> 4 | BD19: =(SUM(BE19,'Run distances (Term 2)'!BI19,'Run distances (Term 3)'!BI19,'Run distances (Term 4)'!BI19)) -> 1.2 | BE19: =(SUM(E19:BB19)*$D$2) -> 1.2
A20: DREY W | B20: 11 | C20: SPENCER | D20: 11DF | BC20: =SUM(E20:BA20) -> 0 | BD20: =(SUM(BE20,'Run distances (Term 2)'!BI20,'Run distances (Term 3)'!BI20,'Run distances (Term 4)'!BI20)) -> 0 | BE20: =(SUM(E20:BB20)*$D$2) -> 0
A21: NOAH MC | B21: 11 | C21: SPENCER | D21: 11DF | E21: 0 | F21: 0 | G21: 2 | H21: 0 | BC21: =SUM(E21:BA21) -> 2 | BD21: =(SUM(BE21,'Run distances (Term 2)'!BI21,'Run distances (Term 3)'!BI21,'Run distances (Term 4)'!BI21)) -> 0.6 | BE21: =(SUM(E21:BB21)*$D$2) -> 0.6
A22: ELIJAH MC | B22: 12 | C22: SPENCER | D22: 12KC | BC22: =SUM(E22:BA22) -> 0 | BD22: =(SUM(BE22,'Run distances (Term 2)'!BI22,'Run distances (Term 3)'!BI22,'Run distances (Term 4)'!BI22)) -> 0 | BE22: =(SUM(E22:BB22)*$D$2) -> 0
A23: WILL C | B23: 3 | C23: SPENCER | D23: 3LB | BC23: =SUM(E23:BA23) -> 0 | BD23: =(SUM(BE23,'Run distances (Term 2)'!BI23,'Run distances (Term 3)'!BI23,'Run distances (Term 4)'!BI23)) -> 9 | BE23: =(SUM(E23:BB23)*$D$2) -> 0
A24: NATE H | B24: 3 | C24: SPENCER | D24: 3LB | M24: 2 | BC24: =SUM(E24:BA24) -> 2 | BD24: =(SUM(BE24,'Run distances (Term 2)'!BI24,'Run distances (Term 3)'!BI24,'Run distances (Term 4)'!BI24)) -> 6.9 | BE24: =(SUM(E24:BB24)*$D$2) -> 0.6
A25: MAEVE H | B25: 3 | C25: SPENCER | D25: 3LB | E25: 0 | F25: 0 | G25: 3 | H25: 2 | L25: 1 | M25: 2 | O25: 1 | P25: 2 | Q25: 1 | T25: 2 | Z25: 1 | AJ25: 2 | AK25: 3 | AL25: 2 | AP25: 2 | BC25: =SUM(E25:BA25) -> 24 | BD25: =(SUM(BE25,'Run distances (Term 2)'!BI25,'Run distances (Term 3)'!BI25,'Run distances (Term 4)'!BI25)) -> 29.1 | BE25: =(SUM(E25:BB25)*$D$2) -> 7.2
A26: LEVI J | B26: 3 | C26: SPENCER | D26: 3LB | BC26: =SUM(E26:BA26) -> 0 | BD26: =(SUM(BE26,'Run distances (Term 2)'!BI26,'Run distances (Term 3)'!BI26,'Run distances (Term 4)'!BI26)) -> 5.7 | BE26: =(SUM(E26:BB26)*$D$2) -> 0
A27: MAX K | B27: 3 | C27: SPENCER | D27: 3LB | E27: 1 | F27: 0 | G27: 4 | H27: 4 | L27: 1 | BC27: =SUM(E27:BA27) -> 10 | BD27: =(SUM(BE27,'Run distances (Term 2)'!BI27,'Run distances (Term 3)'!BI27,'Run distances (Term 4)'!BI27)) -> 26.4 | BE27: =(SUM(E27:BB27)*$D$2) -> 3
A28: ALEX S | B28: 3 | C28: SPENCER | D28: 3LB | BC28: =SUM(E28:BA28) -> 0 | BD28: =(SUM(BE28,'Run distances (Term 2)'!BI28,'Run distances (Term 3)'!BI28,'Run distances (Term 4)'!BI28)) -> 26.1 | BE28: =(SUM(E28:BB28)*$D$2) -> 0
A29: ELSIE D | B29: 5 | C29: SPENCER | D29: 4/5CR | E29: 0 | F29: 0 | G29: 2 | H29: 0 | AT29: 2 | BC29: =SUM(E29:BA29) -> 4 | BD29: =(SUM(BE29,'Run distances (Term 2)'!BI29,'Run distances (Term 3)'!BI29,'Run distances (Term 4)'!BI29)) -> 2.1 | BE29: =(SUM(E29:BB29)*$D$2) -> 1.2
A30: AMELIA C | B30: 5 | C30: SPENCER | D30: 4/5CR | BC30: =SUM(E30:BA30) -> 0 | BD30: =(SUM(BE30,'Run distances (Term 2)'!BI30,'Run distances (Term 3)'!BI30,'Run distances (Term 4)'!BI30)) -> 3.9 | BE30: =(SUM(E30:BB30)*$D$2) -> 0
A31: RYELEY D | B31: 5 | C31: SPENCER | D31: 4/5CR | E31: 0 | F31: 0 | G31: 4 | H31: 0 | T31: 4 | U31: 6 | V31: 7 | W31: 6 | Y31: 2 | AQ31: 2 | BC31: =SUM(E31:BA31) -> 31 | BD31: =(SUM(BE31,'Run distances (Term 2)'!BI31,'Run distances (Term 3)'!BI31,'Run distances (Term 4)'!BI31)) -> 20.7 | BE31: =(SUM(E31:BB31)*$D$2) -> 9.3
A32: LEO G | B32: 5 | C32: SPENCER | D32: 4/5CR | E32: 5 | F32: 6 | G32: 7 | H32: 8 | J32: 4 | K32: 0 | O32: 3 | P32: 9 | Q32: 4 | U32: 5 | V32: 8 | W32: 7 | AJ32: 3 | AK32: 5 | AL32: 6 | AP32: 2 | AQ32: 4 | BA32: 2 | BC32: =SUM(E32:BA32) -> 88 | BD32: =(SUM(BE32,'Run distances (Term 2)'!BI32,'Run distances (Term 3)'!BI32,'Run distances (Term 4)'!BI32)) -> 44.4 | BE32: =(SUM(E32:BB32)*$D$2) -> 26.4
A33: JIMMY H | B33: 5 | C33: SPENCER | D33: 4/5CR | E33: 0 | F33: 0 | G33: 1 | H33: 2 | T33: 3 | V33: 2 | W33: 2 | Z33: 3 | AJ33: 3 | AK33: 4 | AL33: 5 | AO33: 3 | AP33: 3 | AQ33: 1 | BC33: =SUM(E33:BA33) -> 32 | BD33: =(SUM(BE33,'Run distances (Term 2)'!BI33,'Run distances (Term 3)'!BI33,'Run distances (Term 4)'!BI33)) -> 27.9 | BE33: =(SUM(E33:BB33)*$D$2) -> 9.6
A34: OWEN R | B34: 5 | C34: SPENCER | D34: 4/5CR | E34: 0 | F34: 0 | G34: 1 | H34: 2 | J34: 4 | K34: 3 | Z34: 4 | AK34: 3 | AL34: 3 | AP34: 1 | BC34: =SUM(E34:BA34) -> 21 | BD34: =(SUM(BE34,'Run distances (Term 2)'!BI34,'Run distances (Term 3)'!BI34,'Run distances (Term 4)'!BI34)) -> 21.6 | BE34: =(SUM(E34:BB34)*$D$2) -> 6.3
A35: MAGGIE C | B35: 4 | C35: SPENCER | D35: 4JH | E35: 0 | F35: 0 | G35: 3 | H35: 5 | P35: 2 | BC35: =SUM(E35:BA35) -> 10 | BD35: =(SUM(BE35,'Run distances (Term 2)'!BI35,'Run distances (Term 3)'!BI35,'Run distances (Term 4)'!BI35)) -> 12.9 | BE35: =(SUM(E35:BB35)*$D$2) -> 3
A36: KYDEN M | B36: 4 | C36: SPENCER | D36: 4JH | J36: 3 | K36: 0 | P36: 1 | T36: 3 | W36: 3 | AK36: 3 | BC36: =SUM(E36:BA36) -> 13 | BD36: =(SUM(BE36,'Run distances (Term 2)'!BI36,'Run distances (Term 3)'!BI36,'Run distances (Term 4)'!BI36)) -> 16.8 | BE36: =(SUM(E36:BB36)*$D$2) -> 3.9
A37: LIAM R | B37: 4 | C37: SPENCER | D37: 4JH | E37: 0 | F37: 0 | G37: 1 | H37: 2 | J37: 4 | K37: 3 | Z37: 5 | AK37: 4 | AL37: 3 | BC37: =SUM(E37:BA37) -> 22 | BD37: =(SUM(BE37,'Run distances (Term 2)'!BI37,'Run distances (Term 3)'!BI37,'Run distances (Term 4)'!BI37)) -> 15 | BE37: =(SUM(E37:BB37)*$D$2) -> 6.6
A38: BAILEY S | B38: 4 | C38: SPENCER | D38: 4JH | E38: 0 | F38: 1 | G38: 1 | H38: 1 | J38: 0 | K38: 1 | P38: 1 | Q38: 2 | T38: 2 | Y38: 2 | Z38: 2 | AI38: 2 | AL38: 3 | AO38: 2 | AQ38: 2 | BC38: =SUM(E38:BA38) -> 22 | BD38: =(SUM(BE38,'Run distances (Term 2)'!BI38,'Run distances (Term 3)'!BI38,'Run distances (Term 4)'!BI38)) -> 15.3 | BE38: =(SUM(E38:BB38)*$D$2) -> 6.6
A39: ZARA T | B39: 4 | C39: SPENCER | D39: 4JH | E39: 0 | F39: 0 | G39: 1 | H39: 2 | J39: 2 | K39: 0 | M39: 3 | AG39: 4 | AP39: 2 | AQ39: 2 | BC39: =SUM(E39:BA39) -> 16 | BD39: =(SUM(BE39,'Run distances (Term 2)'!BI39,'Run distances (Term 3)'!BI39,'Run distances (Term 4)'!BI39)) -> 17.1 | BE39: =(SUM(E39:BB39)*$D$2) -> 4.8
A40: RHETT W | B40: 4 | C40: SPENCER | D40: 4JH | E40: 0 | F40: 0 | G40: 1 | H40: 1 | M40: 4 | BC40: =SUM(E40:BA40) -> 6 | BD40: =(SUM(BE40,'Run distances (Term 2)'!BI40,'Run distances (Term 3)'!BI40,'Run distances (Term 4)'!BI40)) -> 13.5 | BE40: =(SUM(E40:BB40)*$D$2) -> 1.8
...

Sheet Run distances (Term 2)
A1: Rise and Run Club
B2: Distance per lap (km): | D2: 0.3
E3: Week 1 | J3: Week 2 | O3: Week 3 | T3: Week 4 | Y3: Week 5 | AD3: Week 6 | AI3: Week 7 | AN3: Week 8 | AS3: Week 9 | AX3: Week 10 | BC3: Week 11
A4: Student Name | B4: Year | C4: House | D4: Care Group | E4: Tuesday | F4: Wednesday | G4: Thursday | H4: Friday | J4: Tuesday | K4: Wednesday | L4: Thursday | M4: Friday | O4: Tuesday | P4: Wednesday | Q4: Thursday | R4: Friday | T4: Tuesday | U4: Wednesday | V4: Thursday | W4: Friday | Y4: Tuesday | Z4: Wednesday | AA4: Thursday | AB4: Friday | AD4: Tuesday | AE4: Wednesday | AF4: Thursday | AG4: Friday | AI4: Tuesday | AJ4: Wednesday | AK4: Thursday | AL4: Friday | AN4: Tuesday | AO4: Wednesday | AP4: Thursday | AQ4: Friday | AS4: Tuesday | AT4: Wednesday | AU4: Thursday | AV4: Friday | AX4: Tuesday | AY4: Wednesday | AZ4: Thursday | BA4: Friday | BC4: Tuesday | BD4: Wednesday | BE4: Thursday | BF4: Friday | BH4: Total Term Laps | BI4: Total Term Distance (km)
A5: HARPER J | B5: 1 | C5: SPENCER | D5: 1/2LC | F5: 1 | AL5: 2 | BH5: =SUM(E5:BF5) -> 3 | BI5: =(SUM(E5:BG5)*$D$2) -> 0.9
A6: BEN W | B6: 1 | C6: SPENCER | D6: R/1ZG | BH6: =SUM(E6:BF6) -> 0 | BI6: =(SUM(E6:BG6)*$D$2) -> 0
A7: RYLEE M | B7: 1 | C7: SPENCER | D7: R/1ZG | F7: 1 | BH7: =SUM(E7:BF7) -> 1 | BI7: =(SUM(E7:BG7)*$D$2) -> 0.3
A8: PEYTON V | B8: 1 | C8: SPENCER | D8: R/1ZG | F8: 1 | BH8: =SUM(E8:BF8) -> 1 | BI8: =(SUM(E8:BG8)*$D$2) -> 0.3
A9: MAGGIE S | B9: 1 | C9: SPENCER | D9: R/1ZG | F9: 2 | BH9: =SUM(E9:BF9) -> 2 | BI9: =(SUM(E9:BG9)*$D$2) -> 0.6
A10: ROSIE C | B10: 2 | C10: SPENCER | D10: 1/2LC | F10: 2 | M10: 1 | AL10: 1 | BH10: =SUM(E10:BF10) -> 4 | BI10: =(SUM(E10:BG10)*$D$2) -> 1.2
A11: ERIC D | B11: 2 | C11: SPENCER | D11: 1/2LC | K11: 1 | BH11: =SUM(E11:BF11) -> 1 | BI11: =(SUM(E11:BG11)*$D$2) -> 0.3
A12: HARRISON J | B12: 2 | C12: SPENCER | D12: 1/2LC | BH12: =SUM(E12:BF12) -> 0 | BI12: =(SUM(E12:BG12)*$D$2) -> 0
A13: LELAND J | B13: 2 | C13: SPENCER | D13: 1/2LC | AL13: 2 | BH13: =SUM(E13:BF13) -> 2 | BI13: =(SUM(E13:BG13)*$D$2) -> 0.6
A14: BILLY K | B14: 2 | C14: SPENCER | D14: 1/2LC | BH14: =SUM(E14:BF14) -> 0 | BI14: =(SUM(E14:BG14)*$D$2) -> 0
A15: ALEX Y | B15: 2 | C15: SPENCER | D15: 1/2LC | BH15: =SUM(E15:BF15) -> 0 | BI15: =(SUM(E15:BG15)*$D$2) -> 0
A16: CONNOR C | B16: 10 | C16: SPENCER | D16: 10CF | BH16: =SUM(E16:BF16) -> 0 | BI16: =(SUM(E16:BG16)*$D$2) -> 0
A17: HALEIGH S | B17: 10 | C17: SPENCER | D17: 10CF | BH17: =SUM(E17:BF17) -> 0 | BI17: =(SUM(E17:BG17)*$D$2) -> 0
A18: ANAIS G | B18: 10 | C18: SPENCER | D18: 10CF | BH18: =SUM(E18:BF18) -> 0 | BI18: =(SUM(E18:BG18)*$D$2) -> 0
A19: AXYL W | B19: 11 | C19: SPENCER | D19: 11DF | BH19: =SUM(E19:BF19) -> 0 | BI19: =(SUM(E19:BG19)*$D$2) -> 0
A20: DREY W | B20: 11 | C20: SPENCER | D20: 11DF | BH20: =SUM(E20:BF20) -> 0 | BI20: =(SUM(E20:BG20)*$D$2) -> 0
A21: NOAH MC | B21: 11 | C21: SPENCER | D21: 11DF | BH21: =SUM(E21:BF21) -> 0 | BI21: =(SUM(E21:BG21)*$D$2) -> 0
A22: ELIJAH MC | B22: 12 | C22: SPENCER | D22: 12KC | BH22: =SUM(E22:BF22) -> 0 | BI22: =(SUM(E22:BG22)*$D$2) -> 0
A23: WILL C | B23: 3 | C23: SPENCER | D23: 3LB | BH23: =SUM(E23:BF23) -> 0 | BI23: =(SUM(E23:BG23)*$D$2) -> 0
A24: NATE H | B24: 3 | C24: SPENCER | D24: 3LB | BH24: =SUM(E24:BF24) -> 0 | BI24: =(SUM(E24:BG24)*$D$2) -> 0
A25: MAEVE H | B25: 3 | C25: SPENCER | D25: 3LB | F25: 5 | BH25: =SUM(E25:BF25) -> 5 | BI25: =(SUM(E25:BG25)*$D$2) -> 1.5
A26: LEVI J | B26: 3 | C26: SPENCER | D26: 3LB | BH26: =SUM(E26:BF26) -> 0 | BI26: =(SUM(E26:BG26)*$D$2) -> 0
A27: MAX K | B27: 3 | C27: SPENCER | D27: 3LB | M27: 1 | BH27: =SUM(E27:BF27) -> 1 | BI27: =(SUM(E27:BG27)*$D$2) -> 0.3
A28: ALEX S | B28: 3 | C28: SPENCER | D28: 3LB | M28: 6 | BH28: =SUM(E28:BF28) -> 6 | BI28: =(SUM(E28:BG28)*$D$2) -> 1.8
A29: ELSIE D | B29: 5 | C29: SPENCER | D29: 4/5CR | BH29: =SUM(E29:BF29) -> 0 | BI29: =(SUM(E29:BG29)*$D$2) -> 0
A30: AMELIA C | B30: 5 | C30: SPENCER | D30: 4/5CR | BH30: =SUM(E30:BF30) -> 0 | BI30: =(SUM(E30:BG30)*$D$2) -> 0
A31: RYELEY D | B31: 5 | C31: SPENCER | D31: 4/5CR | BH31: =SUM(E31:BF31) -> 0 | BI31: =(SUM(E31:BG31)*$D$2) -> 0
A32: LEO G | B32: 5 | C32: SPENCER | D32: 4/5CR | BH32: =SUM(E32:BF32) -> 0 | BI32: =(SUM(E32:BG32)*$D$2) -> 0
A33: JIMMY H | B33: 5 | C33: SPENCER | D33: 4/5CR | BH33: =SUM(E33:BF33) -> 0 | BI33: =(SUM(E33:BG33)*$D$2) -> 0
A34: OWEN R | B34: 5 | C34: SPENCER | D34: 4/5CR | BH34: =SUM(E34:BF34) -> 0 | BI34: =(SUM(E34:BG34)*$D$2) -> 0
A35: MAGGIE C | B35: 4 | C35: SPENCER | D35: 4JH | BH35: =SUM(E35:BF35) -> 0 | BI35: =(SUM(E35:BG35)*$D$2) -> 0
A36: KYDEN M | B36: 4 | C36: SPENCER | D36: 4JH | BH36: =SUM(E36:BF36) -> 0 | BI36: =(SUM(E36:BG36)*$D$2) -> 0
A37: LIAM R | B37: 4 | C37: SPENCER | D37: 4JH | AL37: 1 | BH37: =SUM(E37:BF37) -> 1 | BI37: =(SUM(E37:BG37)*$D$2) -> 0.3
A38: BAILEY S | B38: 4 | C38: SPENCER | D38: 4JH | F38: 2 | G38: 1 | BH38: =SUM(E38:BF38) -> 3 | BI38: =(SUM(E38:BG38)*$D$2) -> 0.9
A39: ZARA T | B39: 4 | C39: SPENCER | D39: 4JH | F39: 3 | G39: 1 | J39: 2 | BH39: =SUM(E39:BF39) -> 6 | BI39: =(SUM(E39:BG39)*$D$2) -> 1.8
A40: RHETT W | B40: 4 | C40: SPENCER | D40: 4JH | BH40: =SUM(E40:BF40) -> 0 | BI40: =(SUM(E40:BG40)*$D$2) -> 0
...

Sheet Run distances (Term 3)
A1: Rise and Run Club
B2: Distance per lap (km): | D2: 0.3
E3: Week 1 | J3: Week 2 | O3: Week 3 | T3: Week 4 | Y3: Week 5 | AD3: Week 6 | AI3: Week 7 | AN3: Week 8 | AS3: Week 9 | AX3: Week 10 | BC3: Week 11
A4: Student Name | B4: Year | C4: House | D4: Care Group | E4: Tuesday | F4: Wednesday | G4: Thursday | H4: Friday | J4: Tuesday | K4: Wednesday | L4: Thursday | M4: Friday | O4: Tuesday | P4: Wednesday | Q4: Thursday | R4: Friday | T4: Tuesday | U4: Wednesday | V4: Thursday | W4: Friday | Y4: Tuesday | Z4: Wednesday | AA4: Thursday | AB4: Friday | AD4: Tuesday | AE4: Wednesday | AF4: Thursday | AG4: Friday | AI4: Tuesday | AJ4: Wednesday | AK4: Thursday | AL4: Friday | AN4: Tuesday | AO4: Wednesday | AP4: Thursday | AQ4: Friday | AS4: Tuesday | AT4: Wednesday | AU4: Thursday | AV4: Friday | AX4: Tuesday | AY4: Wednesday | AZ4: Thursday | BA4: Friday | BC4: Tuesday | BD4: Wednesday | BE4: Thursday | BF4: Friday | BH4: Total Term Laps | BI4: Total Term Distance (km)
A5: HARPER J | B5: 1 | C5: SPENCER | D5: 1/2LC | BH5: =SUM(E5:BF5) -> 0 | BI5: =(SUM(E5:BG5)*$D$2) -> 0
A6: ROSIE C | B6: 2 | C6: SPENCER | D6: 1/2LC | BH6: =SUM(E6:BF6) -> 0 | BI6: =(SUM(E6:BG6)*$D$2) -> 0
A7: ERIC D | B7: 2 | C7: SPENCER | D7: 1/2LC | BH7: =SUM(E7:BF7) -> 0 | BI7: =(SUM(E7:BG7)*$D$2) -> 0
A8: HARRISON J | B8: 2 | C8: SPENCER | D8: 1/2LC | BH8: =SUM(E8:BF8) -> 0 | BI8: =(SUM(E8:BG8)*$D$2) -> 0
A9: LELAND J | B9: 2 | C9: SPENCER | D9: 1/2LC | BH9: =SUM(E9:BF9) -> 0 | BI9: =(SUM(E9:BG9)*$D$2) -> 0
A10: BILLY K | B10: 2 | C10: SPENCER | D10: 1/2LC | BH10: =SUM(E10:BF10) -> 0 | BI10: =(SUM(E10:BG10)*$D$2) -> 0
A11: ALEX Y | B11: 2 | C11: SPENCER | D11: 1/2LC | BH11: =SUM(E11:BF11) -> 0 | BI11: =(SUM(E11:BG11)*$D$2) -> 0
A12: CONNOR C | B12: 10 | C12: SPENCER | D12: 10CF | BH12: =SUM(E12:BF12) -> 0 | BI12: =(SUM(E12:BG12)*$D$2) -> 0
A13: Haleigh S | B13: 10 | C13: SPENCER | D13: 10CF | BH13: =SUM(E13:BF13) -> 0 | BI13: =(SUM(E13:BG13)*$D$2) -> 0
A14: ANAIS G | B14: 10 | C14: SPENCER | D14: 10CF | BH14: =SUM(E14:BF14) -> 0 | BI14: =(SUM(E14:BG14)*$D$2) -> 0
A15: AXYL W | B15: 11 | C15: SPENCER | D15: 11DF | BH15: =SUM(E15:BF15) -> 0 | BI15: =(SUM(E15:BG15)*$D$2) -> 0
A16: DREY W | B16: 11 | C16: SPENCER | D16: 11DF | BH16: =SUM(E16:BF16) -> 0 | BI16: =(SUM(E16:BG16)*$D$2) -> 0
... A59: GABRIEL M | B59: 1 | C59: SPENCER | D59: R/1 | BH59: =SUM(E59:BF59) -> 0 | BI59: =(SUM(E59:BG59)*$D$2) -> 0
A60: OLLIE C | B60: RE | C60: SPENCER | D60: RKC | BH60: =SUM(E60:BF60) -> 0 | BI60: =(SUM(E60:BG60)*$D$2) -> 0
A61: Alfie F | B61: RE | C61: SPENCER | D61: RKC | BH61: =SUM(E61:BF61) -> 0 | BI61: =(SUM(E61:BG61)*$D$2) -> 0
A62: Toby J | B62: RE | C62: SPENCER | D62: RKC | BH62: =SUM(E62:BF62) -> 0 | BI62: =(SUM(E62:BG62)*$D$2) -> 0
A63: Indie R | B63: RE | C63: SPENCER | D63: RKC | BH63: =SUM(E63:BF63) -> 0 | BI63: =(SUM(E63:BG63)*$D$2) -> 0
A64: SAM L | B64: 3 | C64: SPENCER | D64: 3LB | BH64: =SUM(E64:BF64) -> 0 | BI64: =(SUM(E64:BG64)*$D$2) -> 0
A65: Mrs C | B65: Teacher | C65: SPENCER | BH65: =SUM(E65:BF65) -> 0 | BI65: =(SUM(E65:BG65)*$D$2) -> 0
BH66: =SUM(E66:BF66) -> 0 | BI66: =(SUM(E66:BG66)*$D$2) -> 0
A67: FINN M | B67: 1 | C67: VINCENT | D67: 1/2LC | BH67: =SUM(E67:BF67) -> 0 | BI67: =(SUM(E67:BG67)*$D$2) -> 0
A68: HARLEE M | B68: 1 | C68: VINCENT | D68: 1/2LC | BH68: =SUM(E68:BF68) -> 0 | BI68: =(SUM(E68:BG68)*$D$2) -> 0
A69: Alison M | B69: 1 | C69: VINCENT | D69: 1/2LC | BH69: =SUM(E69:BF69) -> 0 | BI69: =(SUM(E69:BG69)*$D$2) -> 0
A70: MITCHELL B | B70: 2 | C70: VINCENT | D70: 1/2LC | BH70: =SUM(E70:BF70) -> 0 | BI70: =(SUM(E70:BG70)*$D$2) -> 0
A71: HUGH G | B71: 2 | C71: VINCENT | D71: 1/2LC | BH71: =SUM(E71:BF71) -> 0 | BI71: =(SUM(E71:BG71)*$D$2) -> 0
A72: CHARLIE H | B72: 2 | C72: VINCENT | D72: 1/2LC | BH72: =SUM(E72:BF72) -> 0 | BI72: =(SUM(E72:BG72)*$D$2) -> 0
A73: CLAIRE M | B73: 2 | C73: VINCENT | D73: 1/2LC | BH73: =SUM(E73:BF73) -> 0 | BI73: =(SUM(E73:BG73)*$D$2) -> 0
A74: MAGGIE N | B74: 2 | C74: VINCENT | D74: 1/2LC | BH74: =SUM(E74:BF74) -> 0 | BI74: =(SUM(E74:BG74)*$D$2) -> 0
A75: ARYAN | B75: 2 | C75: VINCENT | D75: 1/2LC | BH75: =SUM(E75:BF75) -> 0 | BI75: =(SUM(E75:BG75)*$D$2) -> 0
A76: GEORGE B | B76: 10 | C76: VINCENT | D76: 10CF | BH76: =SUM(E76:BF76) -> 0 | BI76: =(SUM(E76:BG76)*$D$2) -> 0
A77: HAMISH C | B77: 10 | C77: VINCENT | D77: 10CF | BH77: =SUM(E77:BF77) -> 0 | BI77: =(SUM(E77:BG77)*$D$2) -> 0
A78: Ethan G | B78: 10 | C78: VINCENT | D78: 10CF | BH78: =SUM(E78:BF78) -> 0 | BI78: =(SUM(E78:BG78)*$D$2) -> 0
... A117: TYLER L | B117: 1 | C117: VINCENT | D117: R/1 | BH117: =SUM(E117:BF117) -> 0 | BI117: =(SUM(E117:BG117)*$D$2) -> 0
A118: ADELINE H | B118: RE | C118: VINCENT | D118: RKC | BH118: =SUM(E118:BF118) -> 0 | BI118: =(SUM(E118:BG118)*$D$2) -> 0
A119: Tai S | B119: RE | C119: VINCENT | D119: RKC | BH119: =SUM(E119:BF119) -> 0 | BI119: =(SUM(E119:BG119)*$D$2) -> 0
A120: Summer H | B120: RE | C120: VINCENT | D120: RKC | BH120: =SUM(E120:BF120) -> 0 | BI120: =(SUM(E120:BG120)*$D$2) -> 0
...

Sheet Run distances (Term 4)
A1: Rise and Run Club
B2: Distance per lap (km): | D2: 0.3
E3: Week 1 | J3: Week 2 | O3: Week 3 | T3: Week 4 | Y3: Week 5 | AD3: Week 6 | AI3: Week 7 | AN3: Week 8 | AS3: Week 9 | AX3: Week 10 | BC3: Week 11
A4: Student Name | B4: Year | C4: House | D4: Care Group | E4: Tuesday | F4: Wednesday | G4: Thursday | H4: Friday | J4: Tuesday | K4: Wednesday | L4: Thursday | M4: Friday | O4: Tuesday | P4: Wednesday | Q4: Thursday | R4: Friday | T4: Tuesday | U4: Wednesday | V4: Thursday | W4: Friday | Y4: Tuesday | Z4: Wednesday | AA4: Thursday | AB4: Friday | AD4: Tuesday | AE4: Wednesday | AF4: Thursday | AG4: Friday | AI4: Tuesday | AJ4: Wednesday | AK4: Thursday | AL4: Friday | AN4: Tuesday | AO4: Wednesday | AP4: Thursday | AQ4: Friday | AS4: Tuesday | AT4: Wednesday | AU4: Thursday | AV4: Friday | AX4: Tuesday | AY4: Wednesday | AZ4: Thursday | BA4: Friday | BC4: Tuesday | BD4: Wednesday | BE4: Thursday | BF4: Friday | BH4: Total Term Laps | BI4: Total Term Distance (km)
A5: HARPER J | B5: 1 | C5: SPENCER | D5: 1/2LC | R5: 3 | AG5: 1 | BH5: =SUM(E5:BF5) -> 4 | BI5: =(SUM(E5:BG5)*$D$2) -> 1.2
A6: BEN W | B6: 1 | C6: SPENCER | D6: 1/2LC | G6: 1 | W6: 2 | BH6: =SUM(E6:BF6) -> 3 | BI6: =(SUM(E6:BG6)*$D$2) -> 0.9
A7: RYLEE M | B7: 1 | C7: SPENCER | D7: R/1 | R7: 1 | BH7: =SUM(E7:BF7) -> 1 | BI7: =(SUM(E7:BG7)*$D$2) -> 0.3
A8: PEYTON V | B8: 1 | C8: SPENCER | D8: R/1 | AG8: 2 | BH8: =SUM(E8:BF8) -> 2 | BI8: =(SUM(E8:BG8)*$D$2) -> 0.6
A9: MAGGIE S | B9: 1 | C9: SPENCER | D9: R/1 | G9: 1 | H9: 2 | O9: 3 | Q9: 3 | R9: 4 | U9: 2 | W9: 5 | Y9: 4 | Z9: 3 | AA9: 3 | AD9: 3 | AF9: 2 | AG9: 2 | AJ9: 2 | BH9: =SUM(E9:BF9) -> 39 | BI9: =(SUM(E9:BG9)*$D$2) -> 11.7
A10: ROSIE C | B10: 2 | C10: SPENCER | D10: 1/2LC | R10: 1 | W10: 3 | AB10: 3 | AG10: 2 | BH10: =SUM(E10:BF10) -> 9 | BI10: =(SUM(E10:BG10)*$D$2) -> 2.7
A11: ERIC D | B11: 2 | C11: SPENCER | D11: 1/2LC | BH11: =SUM(E11:BF11) -> 0 | BI11: =(SUM(E11:BG11)*$D$2) -> 0
A12: HARRISON J | B12: 2 | C12: SPENCER | D12: 1/2LC | P12: 5 | Q12: 4 | R12: 8 | BH12: =SUM(E12:BF12) -> 17 | BI12: =(SUM(E12:BG12)*$D$2) -> 5.1
A13: LELAND J | B13: 2 | C13: SPENCER | D13: 1/2LC | BH13: =SUM(E13:BF13) -> 0 | BI13: =(SUM(E13:BG13)*$D$2) -> 0
A14: BILLY K | B14: 2 | C14: SPENCER | D14: 1/2LC | BH14: =SUM(E14:BF14) -> 0 | BI14: =(SUM(E14:BG14)*$D$2) -> 0
A15: ALEX Y | B15: 2 | C15: SPENCER | D15: 1/2LC | BH15: =SUM(E15:BF15) -> 0 | BI15: =(SUM(E15:BG15)*$D$2) -> 0
A16: CONNOR C | B16: 10 | C16: SPENCER | D16: 10CF | R16: 4 | AD16: 6 | BH16: =SUM(E16:BF16) -> 10 | BI16: =(SUM(E16:BG16)*$D$2) -> 3
A17: HALEIGH S | B17: 10 | C17: SPENCER | D17: 10CF | BH17: =SUM(E17:BF17) -> 0 | BI17: =(SUM(E17:BG17)*$D$2) -> 0
A18: ANAIS G | B18: 10 | C18: SPENCER | D18: 10CF | L18: 1 | R18: 3 | W18: 2 | AB18: 1 | BH18: =SUM(E18:BF18) -> 7 | BI18: =(SUM(E18:BG18)*$D$2) -> 2.1
A19: AXYL W | B19: 11 | C19: SPENCER | D19: 11DF | BH19: =SUM(E19:BF19) -> 0 | BI19: =(SUM(E19:BG19)*$D$2) -> 0
A20: DREY W | B20: 11 | C20: SPENCER | D20: 11DF | BH20: =SUM(E20:BF20) -> 0 | BI20: =(SUM(E20:BG20)*$D$2) -> 0
A21: NOAH MC | B21: 11 | C21: SPENCER | D21: 11DF | BH21: =SUM(E21:BF21) -> 0 | BI21: =(SUM(E21:BG21)*$D$2) -> 0
A22: ELIJAH MC | B22: 12 | C22: SPENCER | D22: 12KC | BH22: =SUM(E22:BF22) -> 0 | BI22: =(SUM(E22:BG22)*$D$2) -> 0
A23: WILL C | B23: 3 | C23: SPENCER | D23: 3LB | R23: 8 | W23: 5 | Y23: 4 | AB23: 6 | AD23: 4 | AG23: 3 | BH23: =SUM(E23:BF23) -> 30 | BI23: =(SUM(E23:BG23)*$D$2) -> 9
A24: NATE H | B24: 3 | C24: SPENCER | D24: 3LB | G24: 3 | R24: 8 | W24: 4 | Y24: 1 | Z24: 2 | AJ24: 3 | BH24: =SUM(E24:BF24) -> 21 | BI24: =(SUM(E24:BG24)*$D$2) -> 6.3
A25: MAEVE H | B25: 3 | C25: SPENCER | D25: 3LB | F25: 3 | G25: 3 | H25: 4 | L25: 3 | M25: 4 | O25: 2 | P25: 3 | Q25: 2 | R25: 7 | U25: 4 | W25: 7 | Y25: 4 | Z25: 4 | AB25: 6 | AD25: 4 | AF25: 3 | AG25: 5 | BH25: =SUM(E25:BF25) -> 68 | BI25: =(SUM(E25:BG25)*$D$2) -> 20.4
A26: LEVI J | B26: 3 | C26: SPENCER | D26: 3LB | F26: 2 | L26: 2 | P26: 2 | R26: 7 | W26: 6 | BH26: =SUM(E26:BF26) -> 19 | BI26: =(SUM(E26:BG26)*$D$2) -> 5.7
A27: MAX K | B27: 3 | C27: SPENCER | D27: 3LB | E27: 3 | F27: 1 | G27: 3 | H27: 7 | L27: 6 | M27: 5 | O27: 4 | U27: 2 | W27: 6 | Y27: 5 | Z27: 8 | AD27: 5 | AF27: 6 | AG27: 5 | AI27: 6 | AJ27: 5 | BH27: =SUM(E27:BF27) -> 77 | BI27: =(SUM(E27:BG27)*$D$2) -> 23.1
A28: ALEX S | B28: 3 | C28: SPENCER | D28: 3LB | F28: 4 | G28: 6 | H28: 5 | O28: 3 | P28: 6 | Q28: 3 | R28: 8 | U28: 4 | W28: 9 | Z28: 3 | AB28: 6 | AD28: 3 | AF28: 4 | AG28: 10 | AI28: 4 | AJ28: 3 | BH28: =SUM(E28:BF28) -> 81 | BI28: =(SUM(E28:BG28)*$D$2) -> 24.3
A29: ELSIE D | B29: 5 | C29: SPENCER | D29: 4/5CR | R29: 3 | BH29: =SUM(E29:BF29) -> 3 | BI29: =(SUM(E29:BG29)*$D$2) -> 0.9
A30: AMELIA C | B30: 5 | C30: SPENCER | D30: 4/5CR | G30: 1 | M30: 3 | P30: 1 | R30: 3 | W30: 3 | AB30: 2 | BH30: =SUM(E30:BF30) -> 13 | BI30: =(SUM(E30:BG30)*$D$2) -> 3.9
A31: RYELEY D | B31: 5 | C31: SPENCER | D31: 4/5CR | L31: 6 | M31: 5 | R31: 6 | W31: 7 | AB31: 7 | AG31: 7 | BH31: =SUM(E31:BF31) -> 38 | BI31: =(SUM(E31:BG31)*$D$2) -> 11.4
A32: LEO G | B32: 5 | C32: SPENCER | D32: 4/5CR | G32: 3 | R32: 12 | W32: 12 | Z32: 4 | AA32: 3 | AB32: 13 | AG32: 13 | BH32: =SUM(E32:BF32) -> 60 | BI32: =(SUM(E32:BG32)*$D$2) -> 18
A33: JIMMY H | B33: 5 | C33: SPENCER | D33: 4/5CR | F33: 4 | G33: 3 | H33: 4 | L33: 3 | M33: 5 | O33: 2 | P33: 3 | Q33: 3 | R33: 10 | W33: 9 | AB33: 8 | AG33: 7 | BH33: =SUM(E33:BF33) -> 61 | BI33: =(SUM(E33:BG33)*$D$2) -> 18.3
A34: OWEN R | B34: 5 | C34: SPENCER | D34: 4/5CR | E34: 4 | F34: 4 | G34: 2 | H34: 2 | O34: 5 | Q34: 4 | R34: 6 | W34: 7 | Y34: 3 | AB34: 6 | AG34: 8 | BH34: =SUM(E34:BF34) -> 51 | BI34: =(SUM(E34:BG34)*$D$2) -> 15.3
A35: MAGGIE C | B35: 4 | C35: SPENCER | D35: 4JH | H35: 6 | Q35: 4 | R35: 3 | W35: 4 | Y35: 4 | AB35: 5 | AG35: 7 | BH35: =SUM(E35:BF35) -> 33 | BI35: =(SUM(E35:BG35)*$D$2) -> 9.9
A36: KYDEN M | B36: 4 | C36: SPENCER | D36: 4JH | H36: 5 | R36: 8 | U36: 4 | Z36: 5 | AA36: 5 | AB36: 4 | AD36: 2 | AF36: 2 | AG36: 8 | BH36: =SUM(E36:BF36) -> 43 | BI36: =(SUM(E36:BG36)*$D$2) -> 12.9
A37: LIAM R | B37: 4 | C37: SPENCER | D37: 4JH | H37: 3 | Q37: 2 | W37: 8 | AD37: 2 | AG37: 9 | AI37: 3 | BH37: =SUM(E37:BF37) -> 27 | BI37: =(SUM(E37:BG37)*$D$2) -> 8.1
A38: BAILEY S | B38: 4 | C38: SPENCER | D38: 4JH | H38: 3 | L38: 1 | R38: 4 | U38: 1 | W38: 6 | AA38: 1 | AB38: 4 | AG38: 6 | BH38: =SUM(E38:BF38) -> 26 | BI38: =(SUM(E38:BG38)*$D$2) -> 7.8
A39: ZARA T | B39: 4 | C39: SPENCER | D39: 4JH | G39: 3 | H39: 5 | L39: 4 | P39: 2 | Q39: 3 | U39: 1 | W39: 2 | Z39: 1 | AB39: 8 | AG39: 6 | BH39: =SUM(E39:BF39) -> 35 | BI39: =(SUM(E39:BG39)*$D$2) -> 10.5
A40: RHETT W | B40: 4 | C40: SPENCER | D40: 4JH | H40: 3 | L40: 4 | M40: 4 | R40: 5 | W40: 8 | Z40: 5 | AB40: 4 | AG40: 6 | BH40: =SUM(E40:BF40) -> 39 | BI40: =(SUM(E40:BG40)*$D$2) -> 11.7
...

Sheet Destination Distances
A1: Lap of Yorke Peninsula
B2: Between distances | C2: Accumulative Disctances
A3: Port Wakefield | B3: 25 | C3: 10
A4: Port Clinton | B4: 40 | C4: =C3+B4 -> 50
A5: Ardrossan | B5: 20 | C5: =C4+B5 -> 70
A6: Pine Point | B6: 15 | C6: =C5+B6 -> 85
A7: Port Vincent | B7: 20 | C7: =C6+B7 -> 105
A8: Stansbury | B8: 10 | C8: =C7+B8 -> 115
A9: Wool Bay | B9: 20 | C9: =C8+B9 -> 135
A10: Edithburgh | B10: 15 | C10: =C9+B10 -> 150
A11: Troubridge Point | B11: 50 | C11: =C10+B11 -> 200
A12: Marion Bay | B12: 35 | C12: =C11+B12 -> 235
A13: Corny Point | B13: 30 | C13: =C12+B13 -> 265
A14: Warooka | B14: 20 | C14: =C13+B14 -> 285
A15: Point Turton | B15: 30 | C15: =C14+B15 -> 315
... A20: Wallaroo | B20: 10 | C20: =C19+B20 -> 465
A22: Distances from Minlaton | B22: 0 | C22: Minlaton
A23: Brentwood | B23: 15 | C23: Brentwood
A24: Yorketown | B24: 30 | C24: Yorketown
A25: Port Moorowie | B25: 45 | C25: Port Moorowie
A26: Edithburgh | B26: 50 | C26: Edithburgh
A27: Coobowie | B27: 45 | C27: Coobowie
A28: Wool Bay | B28: 40 | C28: Wool Bay
A29: Stansbury | B29: 40 | C29: Stansbury
A30: Port Vincent | B30: 60 | C30: Port Vincent
A31: Pine Point | B31: 75 | C31: Pine Point
A32: Ardrossan | B32: 90 | C32: Ardrossan
A33: Curramulka | B33: 35 | C33: Curramulka
... A44: Kadina | B44: 120 | C44: Kadina

Sheet Week 2
A1: Baillie Bennett | C1: 7 | D1: 8 | F1: 15
A2: Leo Glazbrook | B2: 5 | C2: 6 | D2: 7 | E2: 8 | F2: 26
A3: Xander Leong | B3: 4 | C3: 7 | D3: 8 | E3: 6 | F3: 25
A4: Liam Pluta | B4: 5 | C4: 7 | D4: 6 | E4: 6 | F4: 24
A5: Livia Pluta | C5: 5 | D5: 6 | E5: 6 | F5: 17
A6: Finn Glazbrook | B6: 4 | C6: 6 | E6: 8 | F6: 18
A7: Maeve Honner | D7: 3 | E7: 2 | F7: 5
A8: Willow Smith | C8: 2 | D8: 5 | E8: 2 | F8: 9
A9: Bailey Smith | C9: 1 | D9: 1 | E9: 1 | F9: 3
A10: Jorja Bennett | B10: 5 | D10: 8 | F10: 13
A11: Rosie Cock | D11: 4 | E11: 2 | F11: 6
A12: Billy Kneebone | B12: 1 | D12: 5 | F12: 6
A13: Max Kneebone | B13: 1 | D13: 4 | E13: 4 | F13: 9
A14: Maggie Cock | D14: 3 | E14: 5 | F14: 8
A15: Ryeley Dutschke | D15: 4 | F15: 4
A16: Eric Dodd | B16: 1 | D16: 2 | E16: 1 | F16: 4
A17: Liam Rohde | D17: 1 | E17: 2 | F17: 3
A18: Gabe McWaters | B18: 2 | D18: 1 | E18: 1 | F18: 4
A19: Elsie Dodd | D19: 2 | F19: 2
A20: Leland Judd | D20: 2 | E20: 1 | F20: 3
A21: Harrison Judd | B21: 1 | D21: 1 | E21: 4 | F21: 6
A22: Noah McDonnell | D22: 2 | F22: 2
A23: Axyl Williams | D23: 2 | F23: 2
A24: Owen Rohde | D24: 1 | E24: 2 | F24: 3
A25: Jimmy Honner | D25: 1 | E25: 2 | F25: 3
A26: Rhett Williams | D26: 1 | E26: 1 | F26: 2
A27: Zara Thomas | D27: 1 | E27: 2 | F27: 3
A28: Aryan Singh | B28: 2 | D28: 5 | F28: 7
A29: Harper Judd | E29: 1 | F29: 1
A30: Alexis Leong | E30: 2 | F30: 2
A31: Henley Dutschke | E31: 1 | F31: 1
A33: YORKE
A34: NAME | B34: Tues | C34: Wed | D34: Thur | E34: Fri | F34: TOTAL
A35: George Preedy | B35: 2 | C35: 5 | D35: 6 | E35: 7 | F35: 20
A36: Bella Weir | E36: 7 | F36: 7
A37: Rose Gibson | E37: 4 | F37: 4
A38: Alfie Crosby | E38: 4 | F38: 4
A39: Dexter Kokar | D39: 1 | E39: 4 | F39: 5
A40: Harry Bray | B40: 5 | C40: 5 | D40: 1 | E40: 4 | F40: 15
A41: Freddy Crosby | E41: 3 | F41: 3
...
